Workbook

Sheet Assumptions
A1: iAutomatia Academy (Hyderabad Center) - Assumptions
A2: All figures are PLANNING ASSUMPTIONS TO VALIDATE (source: founder's brief, Sep 2026). Blue = input you can change; black = calculated; yellow = key lever. Amounts in Rs unless stated.
A4: Programs | B4: Fee (Rs, excl. GST) | C4: Weeks | D4: Hours | E4: Enrolment mix | F4: Notes
A5: Foundation | B5: 35000 | C5: 4 | D5: 80 | E5: 0.4
A6: Integrator | B6: 65000 | C6: 8 | D6: 160 | E6: 0.35
A7: Specialist | B7: 95000 | C7: 12 | D7: 240 | E7: 0.25
A8: Blend (weighted by mix) | B8: =SUMPRODUCT(B5:B7,$E$5:$E$7) -> 60500 | C8: =SUMPRODUCT(C5:C7,$E$5:$E$7) -> 7.4 | D8: =SUMPRODUCT(D5:D7,$E$5:$E$7) -> 148 | E8: =SUM(E5:E7) -> 1 | F8: B8 = blended LIST fee; C8 = average program length in weeks. Mix must total 100%.
A10: Yearly drivers | B10: Y1 (2027) | C10: Y2 (2028) | D10: Y3 (2029) | F10: Notes
A11: Blended effective fee per student (Rs) | B11: 60000 | C11: 62000 | D11: 65000 | F11: Y1 about 1% below list blend (B8) to allow for early-bird/EMI offers; Y2-Y3 assume price increases.
A12: Students enrolled | B12: =N40 -> 204 | C12: 420 | D12: 540 | F12: Y1 = sum of the monthly enrolments in row 40.
A13: Variable cost per student (Rs) | B13: 3000 | C13: 3000 | D13: 3000 | F13: Consumables, kits, certificate, payment/EMI charges.
A14: Corporate / other revenue (Rs) | B14: 1000000 | C14: 4000000 | D14: 7500000 | F14: Corporate upskilling programs, workshops.
A15: Cobot cells added in year | B15: 0 | C15: 2 | D15: 1 | F15: Y2: cells 4-5 (decision Sep 2027); Y3: cell 6.
A16: Cobot cells in operation (year end) | B16: =$B$31+B15 -> 3 | C16: =B16+C15 -> 5 | D16: =C16+D15 -> 6
A19: Fixed operating costs per month (Rs) | B19: Y1 (2027) | C19: Y2 (2028) | D19: Y3 (2029) | F19: Notes
A20: Rent (~2,000 sq ft; larger space from Y2) | B20: 140000 | C20: 160000 | D20: 190000 | F20: Y1 from brief.
A21: Trainers (Y1: 1 lead + 3) | B21: 345000 | C21: 520000 | D21: 690000 | F21: Y1 from brief; trainers added with cells 4-6.
A22: Centre manager + counsellors / placement | B22: 150000 | C22: 220000 | D22: 280000 | F22: Y1: manager + 2 counsellors/placement.
A23: Marketing | B23: 150000 | C23: 250000 | D23: 320000
A24: Utilities, maintenance, consumables | B24: 60000 | C24: 100000 | D24: 135000 | F24: Includes robot AMC from Y2.
A25: Admin | B25: 50000 | C25: 85000 | D25: 135000
A26: Contingency | B26: 5000 | C26: 5000 | D26: 5000 | F26: Rounds Y1 total to Rs 9.0 L/month.
A27: Total fixed opex per month | B27: =SUM(B20:B26) -> 900000 | C27: =SUM(C20:C26) -> 1340000 | D27: =SUM(D20:D26) -> 1755000 | F27: Y2-Y3 line items are estimates sized to the brief's total-cost targets (Rs 1.73 Cr, Rs 2.27 Cr).
A29: Capacity & general | B29: Value | F29: Notes
A30: Launch month | B30: Jan 2027 | F30: First batch.
A31: Cobot cells at launch | B31: 3
A32: Max students per cobot cell | B32: 4
A33: Batch slots per week | B33: 4 | F33: Morning, afternoon, evening (weekdays) + weekend.
A34: Weeks per month | B34: 4.33
A35: Batch size | B35: 12 | F35: 3 cells x 4 students per cell.
A36: Corporate revenue starts in Y1 month # (1 = Jan) | B36: 7 | F36: Y1 corporate revenue spread evenly from this month.
A37: Expansion capex per cobot cell (Rs) | B37: 1600000 | F37: Rs 14 L cobot cell + gripper, Rs 2 L vision sensor (from launch capex).
A39: Year-1 monthly enrolments | B39: Jan-27 | C39: Feb-27 | D39: Mar-27 | E39: Apr-27 | F39: May-27 | G39: Jun-27 | H39: Jul-27 | I39: Aug-27 | J39: Sep-27 | K39: Oct-27 | L39: Nov-27 | M39: Dec-27 | N39: Total
A40: New enrolments | B40: 6 | C40: 8 | D40: 10 | E40: 12 | F40: 14 | G40: 16 | H40: 18 | I40: 20 | J40: 22 | K40: 24 | L40: 26 | M40: 28 | N40: =SUM(B40:M40) -> 204
A42: Launch capex & funding (Rs) | B42: Amount (Rs) | F42: Notes
A43: 3 JAKA cobot cells with grippers | B43: 4200000
A44: 6 PLC trainer kits (Siemens / Mitsubishi / Allen-Bradley) | B44: 900000
A45: 3 vision sensors | B45: 600000
A46: Fit-out (~2,000 sq ft) | B46: 1200000
A47: Laptops | B47: 1000000
...

Sheet Year1_Monthly
A1: Year 1 monthly model (Jan-Dec 2027) - planning assumptions to validate
A2: Month # | B2: 1 | C2: 2 | D2: 3 | E2: 4 | F2: 5 | G2: 6 | H2: 7 | I2: 8 | J2: 9 | K2: 10 | L2: 11 | M2: 12
A3: Rs | B3: =Assumptions!B39 -> Jan-27 | C3: =Assumptions!C39 -> Feb-27 | D3: =Assumptions!D39 -> Mar-27 | E3: =Assumptions!E39 -> Apr-27 | F3: =Assumptions!F39 -> May-27 | G3: =Assumptions!G39 -> Jun-27 | H3: =Assumptions!H39 -> Jul-27 | I3: =Assumptions!I39 -> Aug-27 | ... M3: =Assumptions!M39 -> Dec-27 | N3: Y1 total
A4: New enrolments | B4: =Assumptions!B40 -> 6 | C4: =Assumptions!C40 -> 8 | D4: =Assumptions!D40 -> 10 | E4: =Assumptions!E40 -> 12 | F4: =Assumptions!F40 -> 14 | G4: =Assumptions!G40 -> 16 | H4: =Assumptions!H40 -> 18 | I4: =Assumptions!I40 -> 20 | ... M4: =Assumptions!M40 -> 28 | N4: =SUM(B4:M4) -> 204
A5: Training revenue | B5: =B4*Assumptions!$B$11 -> 360000 | C5: =C4*Assumptions!$B$11 -> 480000 | D5: =D4*Assumptions!$B$11 -> 600000 | E5: =E4*Assumptions!$B$11 -> 720000 | F5: =F4*Assumptions!$B$11 -> 840000 | G5: =G4*Assumptions!$B$11 -> 960000 | H5: =H4*Assumptions!$B$11 -> 1080000 | I5: =I4*Assumptions!$B$11 -> 1200000 | ... M5: =M4*Assumptions!$B$11 -> 1680000 | N5: =SUM(B5:M5) -> 12240000
A6: Corporate / other revenue | B6: =IF(B2>=Assumptions!$B$36,Assumptions!$B$14/(12-Assumptions!$B$36+1),0) -> 0 | C6: =IF(C2>=Assumptions!$B$36,Assumptions!$B$14/(12-Assumptions!$B$36+1),0) -> 0 | D6: =IF(D2>=Assumptions!$B$36,Assumptions!$B$14/(12-Assumptions!$B$36+1),0) -> 0 | E6: =IF(E2>=Assumptions!$B$36,Assumptions!$B$14/(12-Assumptions!$B$36+1),0) -> 0 | F6: =IF(F2>=Assumptions!$B$36,Assumptions!$B$14/(12-Assumptions!$B$36+1),0) -> 0 | G6: =IF(G2>=Assumptions!$B$36,Assumptions!$B$14/(12-Assumptions!$B$36+1),0) -> 0 | H6: =IF(H2>=Assumptions!$B$36,Assumptions!$B$14/(12-Assumptions!$B$36+1),0) -> 166666.67 | I6: =IF(I2>=Assumptions!$B$36,Assumptions!$B$14/(12-Assumptions!$B$36+1),0) -> 166666.67 | ... M6: =IF(M2>=Assumptions!$B$36,Assumptions!$B$14/(12-Assumptions!$B$36+1),0) -> 166666.67 | N6: =SUM(B6:M6) -> 1000000
A7: Total revenue | B7: =B5+B6 -> 360000 | C7: =C5+C6 -> 480000 | D7: =D5+D6 -> 600000 | E7: =E5+E6 -> 720000 | F7: =F5+F6 -> 840000 | G7: =G5+G6 -> 960000 | H7: =H5+H6 -> 1246666.7 | I7: =I5+I6 -> 1366666.7 | ... M7: =M5+M6 -> 1846666.7 | N7: =SUM(B7:M7) -> 13240000
A8: Variable costs | B8: =B4*Assumptions!$B$13 -> 18000 | C8: =C4*Assumptions!$B$13 -> 24000 | D8: =D4*Assumptions!$B$13 -> 30000 | E8: =E4*Assumptions!$B$13 -> 36000 | F8: =F4*Assumptions!$B$13 -> 42000 | G8: =G4*Assumptions!$B$13 -> 48000 | H8: =H4*Assumptions!$B$13 -> 54000 | I8: =I4*Assumptions!$B$13 -> 60000 | ... M8: =M4*Assumptions!$B$13 -> 84000 | N8: =SUM(B8:M8) -> 612000
A9: Fixed operating costs | B9: =Assumptions!$B$27 -> 900000 | C9: =Assumptions!$B$27 -> 900000 | D9: =Assumptions!$B$27 -> 900000 | E9: =Assumptions!$B$27 -> 900000 | F9: =Assumptions!$B$27 -> 900000 | G9: =Assumptions!$B$27 -> 900000 | H9: =Assumptions!$B$27 -> 900000 | I9: =Assumptions!$B$27 -> 900000 | ... M9: =Assumptions!$B$27 -> 900000 | N9: =SUM(B9:M9) -> 10800000
A10: Total costs | B10: =B8+B9 -> 918000 | C10: =C8+C9 -> 924000 | D10: =D8+D9 -> 930000 | E10: =E8+E9 -> 936000 | F10: =F8+F9 -> 942000 | G10: =G8+G9 -> 948000 | H10: =H8+H9 -> 954000 | I10: =I8+I9 -> 960000 | ... M10: =M8+M9 -> 984000 | N10: =SUM(B10:M10) -> 11412000
A11: EBITDA | B11: =B7-B10 -> -558000 | C11: =C7-C10 -> -444000 | D11: =D7-D10 -> -330000 | E11: =E7-E10 -> -216000 | F11: =F7-F10 -> -102000 | G11: =G7-G10 -> 12000 | H11: =H7-H10 -> 292666.67 | I11: =I7-I10 -> 406666.67 | ... M11: =M7-M10 -> 862666.67 | N11: =SUM(B11:M11) -> 1828000
A12: Cumulative EBITDA | B12: =B11 -> -558000 | C12: =B12+C11 -> -1002000 | D12: =C12+D11 -> -1332000 | E12: =D12+E11 -> -1548000 | F12: =E12+F11 -> -1650000 | G12: =F12+G11 -> -1638000 | H12: =G12+H11 -> -1345333.3 | I12: =H12+I11 -> -938666.67 | J12: =I12+J11 -> -418000 | ... M12: =L12+M11 -> 1828000
A13: Break-even enrolments / month | B13: =Assumptions!$B$66 -> 16 | C13: =Assumptions!$B$66 -> 16 | D13: =Assumptions!$B$66 -> 16 | E13: =Assumptions!$B$66 -> 16 | F13: =Assumptions!$B$66 -> 16 | G13: =Assumptions!$B$66 -> 16 | H13: =Assumptions!$B$66 -> 16 | I13: =Assumptions!$B$66 -> 16 | ... M13: =Assumptions!$B$66 -> 16
A14: At or above break-even? | B14: =IF(B4>=B13,"Yes","No") -> No | C14: =IF(C4>=C13,"Yes","No") -> No | D14: =IF(D4>=D13,"Yes","No") -> No | E14: =IF(E4>=E13,"Yes","No") -> No | F14: =IF(F4>=F13,"Yes","No") -> No | G14: =IF(G4>=G13,"Yes","No") -> Yes | H14: =IF(H4>=H13,"Yes","No") -> Yes | I14: =IF(I4>=I13,"Yes","No") -> Yes | ... M14: =IF(M4>=M13,"Yes","No") -> Yes
A15: Capacity check
A16: Est. students in training (approx.) | B16: =B4*Assumptions!$C$8/Assumptions!$B$34 -> 10.254042 | C16: =C4*Assumptions!$C$8/Assumptions!$B$34 -> 13.672055 | D16: =D4*Assumptions!$C$8/Assumptions!$B$34 -> 17.090069 | E16: =E4*Assumptions!$C$8/Assumptions!$B$34 -> 20.508083 | F16: =F4*Assumptions!$C$8/Assumptions!$B$34 -> 23.926097 | G16: =G4*Assumptions!$C$8/Assumptions!$B$34 -> 27.344111 | H16: =H4*Assumptions!$C$8/Assumptions!$B$34 -> 30.762125 | I16: =I4*Assumptions!$C$8/Assumptions!$B$34 -> 34.180139 | ... M16: =M4*Assumptions!$C$8/Assumptions!$B$34 -> 47.852194
A17: Seat capacity (cells x students x slots) | B17: =Assumptions!$B$16*Assumptions!$B$32*Assumptions!$B$33 -> 48 | C17: =Assumptions!$B$16*Assumptions!$B$32*Assumptions!$B$33 -> 48 | D17: =Assumptions!$B$16*Assumptions!$B$32*Assumptions!$B$33 -> 48 | E17: =Assumptions!$B$16*Assumptions!$B$32*Assumptions!$B$33 -> 48 | F17: =Assumptions!$B$16*Assumptions!$B$32*Assumptions!$B$33 -> 48 | G17: =Assumptions!$B$16*Assumptions!$B$32*Assumptions!$B$33 -> 48 | H17: =Assumptions!$B$16*Assumptions!$B$32*Assumptions!$B$33 -> 48 | I17: =Assumptions!$B$16*Assumptions!$B$32*Assumptions!$B$33 -> 48 | ... M17: =Assumptions!$B$16*Assumptions!$B$32*Assumptions!$B$33 -> 48
A18: Capacity utilisation | B18: =IF(B17>0,B16/B17,0) -> 0.21362587 | C18: =IF(C17>0,C16/C17,0) -> 0.28483449 | D18: =IF(D17>0,D16/D17,0) -> 0.35604311 | E18: =IF(E17>0,E16/E17,0) -> 0.42725173 | F18: =IF(F17>0,F16/F17,0) -> 0.49846035 | G18: =IF(G17>0,G16/G17,0) -> 0.56966898 | H18: =IF(H17>0,H16/H17,0) -> 0.6408776 | I18: =IF(I17>0,I16/I17,0) -> 0.71208622 | ... M18: =IF(M17>0,M16/M17,0) -> 0.99692071
A19: Cash (funding less launch capex, plus EBITDA)
A20: Opening cash | B20: =Assumptions!$B$53 -> 2500000 | C20: =B21 -> 1942000 | D20: =C21 -> 1498000 | E20: =D21 -> 1168000 | F20: =E21 -> 952000 | G20: =F21 -> 850000 | H20: =G21 -> 862000 | I20: =H21 -> 1154666.7 | J20: =I21 -> 1561333.3 | ... M20: =L21 -> 3465333.3
A21: Closing cash | B21: =B20+B11 -> 1942000 | C21: =C20+C11 -> 1498000 | D21: =D20+D11 -> 1168000 | E21: =E20+E11 -> 952000 | F21: =F20+F11 -> 850000 | G21: =G20+G11 -> 862000 | H21: =H20+H11 -> 1154666.7 | I21: =I20+I11 -> 1561333.3 | ... M21: =M20+M11 -> 4328000
A22: Revenue is recognised in the month of enrolment (cash basis). EMI collections, GST, taxes and depreciation are not modelled.
A23: Students in training = enrolments x average program weeks / weeks per month (steady-state approximation).

Sheet Projection_3yr
A1: 3-year projection - planning assumptions to validate
A3: Rs | B3: Y1 (2027) | C3: Y2 (2028) | D3: Y3 (2029)
A4: Students enrolled | B4: =Assumptions!B12 -> 204 | C4: =Assumptions!C12 -> 420 | D4: =Assumptions!D12 -> 540
A5: Blended fee per student | B5: =Assumptions!B11 -> 60000 | C5: =Assumptions!C11 -> 62000 | D5: =Assumptions!D11 -> 65000
A6: Training revenue | B6: =B4*B5 -> 12240000 | C6: =C4*C5 -> 26040000 | D6: =D4*D5 -> 35100000
A7: Corporate / other revenue | B7: =Assumptions!B14 -> 1000000 | C7: =Assumptions!C14 -> 4000000 | D7: =Assumptions!D14 -> 7500000
A8: Total revenue | B8: =B6+B7 -> 13240000 | C8: =C6+C7 -> 30040000 | D8: =D6+D7 -> 42600000
A9: Variable costs | B9: =B4*Assumptions!B13 -> 612000 | C9: =C4*Assumptions!C13 -> 1260000 | D9: =D4*Assumptions!D13 -> 1620000
A10: Fixed operating costs | B10: =Assumptions!B27*12 -> 10800000 | C10: =Assumptions!C27*12 -> 16080000 | D10: =Assumptions!D27*12 -> 21060000
A11: Total costs | B11: =B9+B10 -> 11412000 | C11: =C9+C10 -> 17340000 | D11: =D9+D10 -> 22680000
A12: EBITDA | B12: =B8-B11 -> 1828000 | C12: =C8-C11 -> 12700000 | D12: =D8-D11 -> 19920000
A13: EBITDA margin | B13: =IF(B8>0,B12/B8,0) -> 0.13806647 | C13: =IF(C8>0,C12/C8,0) -> 0.42276964 | D13: =IF(D8>0,D12/D8,0) -> 0.46760563
A14: Expansion capex | B14: =Assumptions!B15*Assumptions!$B$37 -> 0 | C14: =Assumptions!C15*Assumptions!$B$37 -> 3200000 | D14: =Assumptions!D15*Assumptions!$B$37 -> 1600000
A15: Cash flow after expansion capex | B15: =B12-B14 -> 1828000 | C15: =C12-C14 -> 9500000 | D15: =D12-D14 -> 18320000
A16: Cumulative cash after launch capex | B16: =-Assumptions!B51+B15 -> -7672000 | C16: =B16+C15 -> 1828000 | D16: =C16+D15 -> 20148000
A18: Capacity check | B18: Y1 (2027) | C18: Y2 (2028) | D18: Y3 (2029)
A19: Cobot cells in operation (year end) | B19: =Assumptions!B16 -> 3 | C19: =Assumptions!C16 -> 5 | D19: =Assumptions!D16 -> 6
A20: Seat capacity (cells x students x slots) | B20: =B19*Assumptions!$B$32*Assumptions!$B$33 -> 48 | C20: =C19*Assumptions!$B$32*Assumptions!$B$33 -> 80 | D20: =D19*Assumptions!$B$32*Assumptions!$B$33 -> 96
A21: Avg students in training (approx.) | B21: =B4/12*Assumptions!$C$8/Assumptions!$B$34 -> 29.053118 | C21: =C4/12*Assumptions!$C$8/Assumptions!$B$34 -> 59.815242 | D21: =D4/12*Assumptions!$C$8/Assumptions!$B$34 -> 76.905312
A22: Average utilisation | B22: =IF(B20>0,B21/B20,0) -> 0.60527329 | C22: =IF(C20>0,C21/C20,0) -> 0.74769053 | D22: =IF(D20>0,D21/D20,0) -> 0.801097
A23: Y1 average understates the year-end peak: see Year1_Monthly row 18 (Dec 2027 reaches about 100% on 3 cells).
A25: Summary (Rs Cr) | B25: Y1 (2027) | C25: Y2 (2028) | D25: Y3 (2029)
A26: Students | B26: =B4 -> 204 | C26: =C4 -> 420 | D26: =D4 -> 540
A27: Blended fee (Rs '000) | B27: =B5/1000 -> 60 | C27: =C5/1000 -> 62 | D27: =D5/1000 -> 65
A28: Training revenue | B28: =B6/10^7 -> 1.224 | C28: =C6/10^7 -> 2.604 | D28: =D6/10^7 -> 3.51
A29: Corporate / other | B29: =B7/10^7 -> 0.1 | C29: =C7/10^7 -> 0.4 | D29: =D7/10^7 -> 0.75
A30: Total revenue | B30: =B8/10^7 -> 1.324 | C30: =C8/10^7 -> 3.004 | D30: =D8/10^7 -> 4.26
A31: Total costs | B31: =B11/10^7 -> 1.1412 | C31: =C11/10^7 -> 1.734 | D31: =D11/10^7 -> 2.268
A32: EBITDA | B32: =B12/10^7 -> 0.1828 | C32: =C12/10^7 -> 1.27 | D32: =D12/10^7 -> 1.992
A33: Expansion capex | B33: =B14/10^7 -> 0 | C33: =C14/10^7 -> 0.32 | D33: =D14/10^7 -> 0.16
A35: Checks | B35: Value
A36: Y1 EBITDA: annual minus monthly model (should be 0) | B36: =ROUND(B12-Year1_Monthly!N11,0) -> 0
A37: Program mix totals 100% | B37: =IF(ROUND(Assumptions!E8,4)=1,"OK","CHECK") -> OK
